Workbook

Sheet Cover
B2: BuildAI — Financial Model
B3: Cohort economics, multi-year revenue & cost projection, sensitivity analysis
B4: Internal working document — Sharad Agrawal
B6: Color conventions
B7: Blue text | C7: Hardcoded inputs — change these to model different scenarios
B8: Black text | C8: Excel formulas / calculations — do not edit directly
B9: Green text | C9: Cross-sheet links — reference values from other tabs
B10: Yellow background | C10: Key assumption — review before using the model
B12: Sheets in this workbook
B13: Assumptions | C13: All editable inputs in one place
B14: Per-Cohort | C14: Single-cohort revenue, cost, gross margin
B15: Multi-Year | C15: 5-year revenue, cost, and margin projection
B16: Phase 2 | C16: Startup placement & hiring fee model (Year 1 onwards)
B17: Sensitivity | C17: What happens at different price points and cohort sizes

Sheet Assumptions
B2: Assumptions
B3: Every blue cell is an editable input. Modify to model scenarios.
B5: PRICING
B6: Student-facing program fee (INR) | C6: 22500 | D6: Mid-point of ₹20K–₹25K band
B7: College administrative margin per student (INR) | C7: 6000 | D7: Mid-point of ₹5K–₹7K
B8: BuildAI revenue per student (INR) | C8: =C6-C7 -> 16500 | D8: Derived: student fee minus college margin
B10: COHORT STRUCTURE
B11: Students per cohort | C11: 100 | D11: Target operational sweet spot
B12: Cohort duration (weeks) | C12: 13 | D12: Standard 13-week program
B13: Lead mentors per cohort | C13: 4 | D13: 1 lead mentor per ~25 students + peer review
B14: Students per lead mentor | C14: =C11/C13 -> 25 | D14: Derived
B15: Cohorts per college per year | C15: 2 | D15: Summer + winter typical
B17: COSTS PER COHORT
B18: Mentor pay per mentor per week (INR) | C18: 15000 | D18: Per lead mentor, ~5 hours commitment
B19: Total mentor cost per cohort (INR) | C19: =C18*C13*C12 -> 780000 | D19: Derived: per-week × mentors × weeks
B20: Platform/tool cost per cohort (INR) | C20: 50000 | D20: Anthropic API, Vercel, Supabase, etc.
B21: External reviewer honorariums per cohort (INR) | C21: 40000 | D21: 5 reviewers × ₹8K
B22: Ops/coordination allocated per cohort (INR) | C22: 100000 | D22: Allocated India ops + tools
B23: Total cost per cohort (INR) | C23: =C19+C20+C21+C22 -> 970000 | D23: Sum of all cohort costs
B25: GROWTH PROJECTION (COLLEGES PARTNERED)
B26: Year 1 colleges | C26: 3 | D26: Pilot + 2 ramp
B27: Year 2 colleges | C27: 8 | D27: Conservative growth
B28: Year 3 colleges | C28: 20 | D28: Distribution unlock
B29: Year 4 colleges | C29: 40 | D29: Scaling proven model
B30: Year 5 colleges | C30: 70 | D30: Mature network
B32: PHASE 2 — STARTUP PLACEMENT
B33: Distinction graduates per cohort (%) | C33: 0.12 | D33: Top 10–15% of cohort
B34: % of distinction grads placed | C34: 0.5 | D34: Half opt for startup placement
B35: Avg startup placement fee per intern (INR) | C35: 35000 | D35: ₹25K–₹50K band
B36: % of placed interns converting to FT hire | C36: 0.3 | D36: Industry-typical conversion
B37: Avg first-year FT compensation (INR) | C37: 1500000 | D37: ₹15 LPA AI-startup hire
B38: BuildAI hiring fee rate | C38: 0.1 | D38: 10% of first-year comp

Sheet Per-Cohort
B2: Per-Cohort Economics
B3: Revenue, cost, and gross margin for a single 100-student cohort
B5: LINE ITEM | C5: AMOUNT (INR) | D5: FORMULA / SOURCE
B6: REVENUE
B7: Students enrolled | C7: =Assumptions!C11 -> 100 | D7: From Assumptions
B8: BuildAI revenue per student | C8: =Assumptions!C8 -> 16500 | D8: From Assumptions (student fee minus college margin)
B9: Total cohort revenue | C9: =C7*C8 -> 1650000 | D9: Students × revenue per student
B11: COSTS
B12: Mentor costs | C12: =Assumptions!C19 -> 780000 | D12: Per-pod-week × pods × weeks
B13: Platform / tool costs | C13: =Assumptions!C20 -> 50000 | D13: Anthropic, OpenAI, Vercel, etc.
B14: Ops / coordination (allocated) | C14: =Assumptions!C22 -> 100000 | D14: Allocated India ops cost
B15: External reviewer honorariums | C15: =Assumptions!C21 -> 40000 | D15: 5 reviewers × ₹8K
B16: Total cohort cost | C16: =SUM(C12:C15) -> 970000 | D16: Sum of all cohort costs
B18: GROSS MARGIN
B19: Gross profit per cohort | C19: =C9-C16 -> 680000 | D19: Revenue minus total cost
B20: Gross margin % | C20: =C19/C9 -> 0.41212121 | D20: Gross profit / revenue
B21: Gross profit per student | C21: =C19/C7 -> 6800 | D21: Gross profit / students enrolled

Sheet Multi-Year
B2: 5-Year Revenue Projection
B3: Phase 1 (college program) revenue. Phase 2 startup placement modeled separately.
B5: METRIC | C5: Year 1 | D5: Year 2 | E5: Year 3 | F5: Year 4 | G5: Year 5
B6: Partner colleges | C6: =Assumptions!C26 -> 3 | D6: =Assumptions!C27 -> 8 | E6: =Assumptions!C28 -> 20 | F6: =Assumptions!C29 -> 40 | G6: =Assumptions!C30 -> 70
B7: Cohorts (colleges × cohorts/year) | C7: =C6*Assumptions!C15 -> 6 | D7: =D6*Assumptions!C15 -> 16 | E7: =E6*Assumptions!C15 -> 40 | F7: =F6*Assumptions!C15 -> 80 | G7: =G6*Assumptions!C15 -> 140
B8: Students enrolled | C8: =C7*Assumptions!C11 -> 600 | D8: =D7*Assumptions!C11 -> 1600 | E8: =E7*Assumptions!C11 -> 4000 | F8: =F7*Assumptions!C11 -> 8000 | G8: =G7*Assumptions!C11 -> 14000
B10: Revenue
B11: Phase 1 revenue (INR) | C11: =C8*Assumptions!C8 -> 9900000 | D11: =D8*Assumptions!C8 -> 26400000 | E11: =E8*Assumptions!C8 -> 66000000 | F11: =F8*Assumptions!C8 -> 132000000 | G11: =G8*Assumptions!C8 -> 231000000
B12: Phase 2 revenue (INR) | C12: ='Phase 2'!C13*0.5 -> 1440000 | D12: ='Phase 2'!D13 -> 7680000 | E12: ='Phase 2'!E13 -> 19200000 | F12: ='Phase 2'!F13 -> 38400000 | G12: ='Phase 2'!G13 -> 67200000
B13: Total revenue (INR) | C13: =C11+C12 -> 11340000 | D13: =D11+D12 -> 34080000 | E13: =E11+E12 -> 85200000 | F13: =F11+F12 -> 170400000 | G13: =G11+G12 -> 298200000
B15: Costs
B16: Phase 1 cohort costs (INR) | C16: =C7*Assumptions!C23 -> 5820000 | D16: =D7*Assumptions!C23 -> 15520000 | E16: =E7*Assumptions!C23 -> 38800000 | F16: =F7*Assumptions!C23 -> 77600000 | G16: =G7*Assumptions!C23 -> 135800000
B17: Fixed overhead (founders + central ops, INR) | C17: 3000000 | D17: 6000000 | E17: 12000000 | F17: 20000000 | G17: 30000000
B18: Total costs (INR) | C18: =C16+C17 -> 8820000 | D18: =D16+D17 -> 21520000 | E18: =E16+E17 -> 50800000 | F18: =F16+F17 -> 97600000 | G18: =G16+G17 -> 165800000
B20: Profitability
B21: EBITDA (INR) | C21: =C13-C18 -> 2520000 | D21: =D13-D18 -> 12560000 | E21: =E13-E18 -> 34400000 | F21: =F13-F18 -> 72800000 | G21: =G13-G18 -> 132400000
B22: EBITDA margin % | C22: =IFERROR(C21/C13,0) -> 0.22222222 | D22: =IFERROR(D21/D13,0) -> 0.3685446 | E22: =IFERROR(E21/E13,0) -> 0.40375587 | F22: =IFERROR(F21/F13,0) -> 0.42723005 | G22: =IFERROR(G21/G13,0) -> 0.44399732
B24: Revenue in ₹ crore (display) | C24: =C13/10000000 -> 1.134 | D24: =D13/10000000 -> 3.408 | E24: =E13/10000000 -> 8.52 | F24: =F13/10000000 -> 17.04 | G24: =G13/10000000 -> 29.82

Sheet Phase 2
B2: Phase 2 — Startup Placement Revenue
B3: Internship placement fees + full-time hiring fees, activated end of Year 1
B5: METRIC | C5: Year 1 | D5: Year 2 | E5: Year 3 | F5: Year 4 | G5: Year 5
B6: Total students enrolled | C6: ='Multi-Year'!C8 -> 600 | D6: ='Multi-Year'!D8 -> 1600 | E6: ='Multi-Year'!E8 -> 4000 | F6: ='Multi-Year'!F8 -> 8000 | G6: ='Multi-Year'!G8 -> 14000
B7: Distinction graduates | C7: =C6*Assumptions!C33 -> 72 | D7: =D6*Assumptions!C33 -> 192 | E7: =E6*Assumptions!C33 -> 480 | F7: =F6*Assumptions!C33 -> 960 | G7: =G6*Assumptions!C33 -> 1680
B8: Interns placed at startups | C8: =C7*Assumptions!C34 -> 36 | D8: =D7*Assumptions!C34 -> 96 | E8: =E7*Assumptions!C34 -> 240 | F8: =F7*Assumptions!C34 -> 480 | G8: =G7*Assumptions!C34 -> 840
B10: Revenue streams
B11: Internship placement fee revenue (INR) | C11: =C8*Assumptions!C35 -> 1260000 | D11: =D8*Assumptions!C35 -> 3360000 | E11: =E8*Assumptions!C35 -> 8400000 | F11: =F8*Assumptions!C35 -> 16800000 | G11: =G8*Assumptions!C35 -> 29400000
B12: Full-time hires (INR) | C12: =C8*Assumptions!C36*Assumptions!C37*Assumptions!C38 -> 1620000 | D12: =D8*Assumptions!C36*Assumptions!C37*Assumptions!C38 -> 4320000 | E12: =E8*Assumptions!C36*Assumptions!C37*Assumptions!C38 -> 10800000 | F12: =F8*Assumptions!C36*Assumptions!C37*Assumptions!C38 -> 21600000 | G12: =G8*Assumptions!C36*Assumptions!C37*Assumptions!C38 -> 37800000
B13: Phase 2 total revenue (INR) | C13: =C11+C12 -> 2880000 | D13: =D11+D12 -> 7680000 | E13: =E11+E12 -> 19200000 | F13: =F11+F12 -> 38400000 | G13: =G11+G12 -> 67200000
B15: Phase 2 in ₹ crore (display) | C15: =C13/10000000 -> 0.288 | D15: =D13/10000000 -> 0.768 | E15: =E13/10000000 -> 1.92 | F15: =F13/10000000 -> 3.84 | G15: =G13/10000000 -> 6.72

Sheet Sensitivity
B2: Sensitivity Analysis
B3: Per-cohort gross margin at different prices and cohort sizes
B5: Per-cohort gross margin (INR)
B7: Price ↓ / Cohort size → | C7: 30 | D7: 50 | E7: 75 | F7: 100 | G7: 125 | H7: 150
B8: ₹10,000 per student | C8: =30*10000-(CEILING(30/25,1)*Assumptions!C18*Assumptions!C12+Assumptions!C20+Assumptions!C21+Assumptions!C22) -> -280000 | D8: =50*10000-(CEILING(50/25,1)*Assumptions!C18*Assumptions!C12+Assumptions!C20+Assumptions!C21+Assumptions!C22) -> -80000 | E8: =75*10000-(CEILING(75/25,1)*Assumptions!C18*Assumptions!C12+Assumptions!C20+Assumptions!C21+Assumptions!C22) -> -25000 | F8: =100*10000-(CEILING(100/25,1)*Assumptions!C18*Assumptions!C12+Assumptions!C20+Assumptions!C21+Assumptions!C22) -> 30000 | G8: =125*10000-(CEILING(125/25,1)*Assumptions!C18*Assumptions!C12+Assumptions!C20+Assumptions!C21+Assumptions!C22) -> 85000 | H8: =150*10000-(CEILING(150/25,1)*Assumptions!C18*Assumptions!C12+Assumptions!C20+Assumptions!C21+Assumptions!C22) -> 140000
B9: ₹13,000 per student | C9: =30*13000-(CEILING(30/25,1)*Assumptions!C18*Assumptions!C12+Assumptions!C20+Assumptions!C21+Assumptions!C22) -> -190000 | D9: =50*13000-(CEILING(50/25,1)*Assumptions!C18*Assumptions!C12+Assumptions!C20+Assumptions!C21+Assumptions!C22) -> 70000 | E9: =75*13000-(CEILING(75/25,1)*Assumptions!C18*Assumptions!C12+Assumptions!C20+Assumptions!C21+Assumptions!C22) -> 200000 | F9: =100*13000-(CEILING(100/25,1)*Assumptions!C18*Assumptions!C12+Assumptions!C20+Assumptions!C21+Assumptions!C22) -> 330000 | G9: =125*13000-(CEILING(125/25,1)*Assumptions!C18*Assumptions!C12+Assumptions!C20+Assumptions!C21+Assumptions!C22) -> 460000 | H9: =150*13000-(CEILING(150/25,1)*Assumptions!C18*Assumptions!C12+Assumptions!C20+Assumptions!C21+Assumptions!C22) -> 590000
B10: ₹16,500 per student | C10: =30*16500-(CEILING(30/25,1)*Assumptions!C18*Assumptions!C12+Assumptions!C20+Assumptions!C21+Assumptions!C22) -> -85000 | D10: =50*16500-(CEILING(50/25,1)*Assumptions!C18*Assumptions!C12+Assumptions!C20+Assumptions!C21+Assumptions!C22) -> 245000 | E10: =75*16500-(CEILING(75/25,1)*Assumptions!C18*Assumptions!C12+Assumptions!C20+Assumptions!C21+Assumptions!C22) -> 462500 | F10: =100*16500-(CEILING(100/25,1)*Assumptions!C18*Assumptions!C12+Assumptions!C20+Assumptions!C21+Assumptions!C22) -> 680000 | G10: =125*16500-(CEILING(125/25,1)*Assumptions!C18*Assumptions!C12+Assumptions!C20+Assumptions!C21+Assumptions!C22) -> 897500 | H10: =150*16500-(CEILING(150/25,1)*Assumptions!C18*Assumptions!C12+Assumptions!C20+Assumptions!C21+Assumptions!C22) -> 1115000
B11: ₹20,000 per student | C11: =30*20000-(CEILING(30/25,1)*Assumptions!C18*Assumptions!C12+Assumptions!C20+Assumptions!C21+Assumptions!C22) -> 20000 | D11: =50*20000-(CEILING(50/25,1)*Assumptions!C18*Assumptions!C12+Assumptions!C20+Assumptions!C21+Assumptions!C22) -> 420000 | E11: =75*20000-(CEILING(75/25,1)*Assumptions!C18*Assumptions!C12+Assumptions!C20+Assumptions!C21+Assumptions!C22) -> 725000 | F11: =100*20000-(CEILING(100/25,1)*Assumptions!C18*Assumptions!C12+Assumptions!C20+Assumptions!C21+Assumptions!C22) -> 1030000 | G11: =125*20000-(CEILING(125/25,1)*Assumptions!C18*Assumptions!C12+Assumptions!C20+Assumptions!C21+Assumptions!C22) -> 1335000 | H11: =150*20000-(CEILING(150/25,1)*Assumptions!C18*Assumptions!C12+Assumptions!C20+Assumptions!C21+Assumptions!C22) -> 1640000
B12: ₹25,000 per student | C12: =30*25000-(CEILING(30/25,1)*Assumptions!C18*Assumptions!C12+Assumptions!C20+Assumptions!C21+Assumptions!C22) -> 170000 | D12: =50*25000-(CEILING(50/25,1)*Assumptions!C18*Assumptions!C12+Assumptions!C20+Assumptions!C21+Assumptions!C22) -> 670000 | E12: =75*25000-(CEILING(75/25,1)*Assumptions!C18*Assumptions!C12+Assumptions!C20+Assumptions!C21+Assumptions!C22) -> 1100000 | F12: =100*25000-(CEILING(100/25,1)*Assumptions!C18*Assumptions!C12+Assumptions!C20+Assumptions!C21+Assumptions!C22) -> 1530000 | G12: =125*25000-(CEILING(125/25,1)*Assumptions!C18*Assumptions!C12+Assumptions!C20+Assumptions!C21+Assumptions!C22) -> 1960000 | H12: =150*25000-(CEILING(150/25,1)*Assumptions!C18*Assumptions!C12+Assumptions!C20+Assumptions!C21+Assumptions!C22) -> 2390000
B16: 5-year cumulative revenue scenarios
B18: Scenario | C18: Y1 | D18: Y2 | E18: Y3 | F18: Y4 | G18: Y5 | H18: Cumulative ₹cr
B19: Conservative (slower college acquisition) | C19: =2*Assumptions!$C$15*Assumptions!$C$11*Assumptions!$C$8 -> 6600000 | D19: =5*Assumptions!$C$15*Assumptions!$C$11*Assumptions!$C$8 -> 16500000 | E19: =12*Assumptions!$C$15*Assumptions!$C$11*Assumptions!$C$8 -> 39600000 | F19: =24*Assumptions!$C$15*Assumptions!$C$11*Assumptions!$C$8 -> 79200000 | G19: =40*Assumptions!$C$15*Assumptions!$C$11*Assumptions!$C$8 -> 132000000 | H19: =SUM(C19:G19)/10000000 -> 27.39
B20: Base case (current assumptions) | C20: =3*Assumptions!$C$15*Assumptions!$C$11*Assumptions!$C$8 -> 9900000 | D20: =8*Assumptions!$C$15*Assumptions!$C$11*Assumptions!$C$8 -> 26400000 | E20: =20*Assumptions!$C$15*Assumptions!$C$11*Assumptions!$C$8 -> 66000000 | F20: =40*Assumptions!$C$15*Assumptions!$C$11*Assumptions!$C$8 -> 132000000 | G20: =70*Assumptions!$C$15*Assumptions!$C$11*Assumptions!$C$8 -> 231000000 | H20: =SUM(C20:G20)/10000000 -> 46.53
B21: Aggressive (faster network effects) | C21: =4*Assumptions!$C$15*Assumptions!$C$11*Assumptions!$C$8 -> 13200000 | D21: =12*Assumptions!$C$15*Assumptions!$C$11*Assumptions!$C$8 -> 39600000 | E21: =30*Assumptions!$C$15*Assumptions!$C$11*Assumptions!$C$8 -> 99000000 | F21: =60*Assumptions!$C$15*Assumptions!$C$11*Assumptions!$C$8 -> 198000000 | G21: =100*Assumptions!$C$15*Assumptions!$C$11*Assumptions!$C$8 -> 330000000 | H21: =SUM(C21:G21)/10000000 -> 67.98
B23: Notes
B24: 1. Sensitivity table assumes pods scale with cohort size (1 mentor pod per 12 students).
B25: 2. Base case = current Assumptions sheet values.
B26: 3. Phase 2 revenue (startup placement) excluded from these projections — see Phase 2 tab.
B27: 4. ₹1 crore = ₹10,000,000 = ~$120,000 USD at typical exchange rates.

Sheet AI Token Costs
B2: Student AI Access — Token Cost Model
B3: Per-student API spend via OpenRouter, frontier vs cheap models. Blue cells are editable.
B5: GLOBAL INPUT
B6: USD → INR exchange rate | C6: 95.2 | D6: Editable. ~Jun 2026 spot
B8: MODEL PRICES — USD per 1M tokens (OpenRouter, Jun 2026)
B9: Model | C9: Input $/1M | D9: Output $/1M | E9: Tier
B10: Claude Sonnet 4.6 | C10: 3 | D10: 15 | E10: Frontier
B11: GPT-5.4 | C11: 2.5 | D11: 15 | E11: Frontier
B12: Gemini 3.5 Flash | C12: 1.5 | D12: 9 | E12: Mid
B13: Claude Haiku 4.5 | C13: 1 | D13: 5 | E13: Mid
B14: GPT-5.4-mini | C14: 0.75 | D14: 4.5 | E14: Mid
B15: DeepSeek V4-pro | C15: 0.44 | D15: 0.87 | E15: Cheap / open
B16: Qwen 3.7-Plus | C16: 0.4 | D16: 1.6 | E16: Cheap / open
B17: MiniMax M2 | C17: 0.255 | D17: 1 | E17: Cheap / open
B18: DeepSeek V4-flash | C18: 0.1 | D18: 0.2 | E18: Cheap / open
B20: USAGE PER STUDENT — tokens in MILLIONS
B21: Scenario | C21: Input (M) | D21: Output (M)
B22: Light builder (13 wks) | C22: 25 | D22: 4
B23: Typical builder (13 wks) | C23: 60 | D23: 9
B24: Heavy builder (13 wks) | C24: 120 | D24: 18
B25: Capstone only — full AI product (wks 11-13) | C25: 50 | D25: 8
B26: Dev-time coding assistance dominates; product inference (RAG/agents) folded in. Edit freely.
B28: PER-STUDENT COST (Typical 13-wk vs Capstone build)
B29: Model | C29: Typical USD | D29: Typical INR | E29: Capstone USD | F29: Capstone INR
B30: =B10 -> Claude Sonnet 4.6 | C30: =$C$23*C10+$D$23*D10 -> 315 | D30: =C30*$C$6 -> 29988 | E30: =$C$25*C10+$D$25*D10 -> 270 | F30: =E30*$C$6 -> 25704
B31: =B11 -> GPT-5.4 | C31: =$C$23*C11+$D$23*D11 -> 285 | D31: =C31*$C$6 -> 27132 | E31: =$C$25*C11+$D$25*D11 -> 245 | F31: =E31*$C$6 -> 23324
B32: =B12 -> Gemini 3.5 Flash | C32: =$C$23*C12+$D$23*D12 -> 171 | D32: =C32*$C$6 -> 16279.2 | E32: =$C$25*C12+$D$25*D12 -> 147 | F32: =E32*$C$6 -> 13994.4
B33: =B13 -> Claude Haiku 4.5 | C33: =$C$23*C13+$D$23*D13 -> 105 | D33: =C33*$C$6 -> 9996 | E33: =$C$25*C13+$D$25*D13 -> 90 | F33: =E33*$C$6 -> 8568
B34: =B14 -> GPT-5.4-mini | C34: =$C$23*C14+$D$23*D14 -> 85.5 | D34: =C34*$C$6 -> 8139.6 | E34: =$C$25*C14+$D$25*D14 -> 73.5 | F34: =E34*$C$6 -> 6997.2
B35: =B15 -> DeepSeek V4-pro | C35: =$C$23*C15+$D$23*D15 -> 34.23 | D35: =C35*$C$6 -> 3258.696 | E35: =$C$25*C15+$D$25*D15 -> 28.96 | F35: =E35*$C$6 -> 2756.992
B36: =B16 -> Qwen 3.7-Plus | C36: =$C$23*C16+$D$23*D16 -> 38.4 | D36: =C36*$C$6 -> 3655.68 | E36: =$C$25*C16+$D$25*D16 -> 32.8 | F36: =E36*$C$6 -> 3122.56
B37: =B17 -> MiniMax M2 | C37: =$C$23*C17+$D$23*D17 -> 24.3 | D37: =C37*$C$6 -> 2313.36 | E37: =$C$25*C17+$D$25*D17 -> 20.75 | F37: =E37*$C$6 -> 1975.4
B38: =B18 -> DeepSeek V4-flash | C38: =$C$23*C18+$D$23*D18 -> 7.8 | D38: =C38*$C$6 -> 742.56 | E38: =$C$25*C18+$D$25*D18 -> 6.6 | F38: =E38*$C$6 -> 628.32
B40: COHORT & MARGIN IMPACT — 100 students, Typical usage
B41: Students per cohort | C41: =Assumptions!C11 -> 100
B42: Current platform/tool assumption per cohort (INR) | C42: =Assumptions!C20 -> 50000
B43: BuildAI revenue per cohort (INR) | C43: =per-cohort!c9 -> #NAME?
B44: AI cost per cohort — ALL-FRONTIER (Sonnet) | C44: =D30*Assumptions!C11 -> 2998800
B45: AI cost per cohort — ALL-CHEAP (DeepSeek V4-pro) | C45: =D35*Assumptions!C11 -> 325869.6
B46: AI cost per cohort — cheap + 70% education credits | C46: =D35*Assumptions!C11*0.3 -> 97760.88
...
